=== DADOS REAIS PARA CORREÇÃO DO RELATÓRIO ===
Total: 703 respondentes

1. GÊNERO:
   Feminino: 432 (61.5%)
   Masculino: 269 (38.3%)
   Outro: 2 (0.3%)

2. ESCOLARIDADE:
Traceback (most recent call last):
  File "C:\Users\brsamd00\AppData\Roaming\Python\Python312\site-packages\pandas\core\indexes\base.py", line 3805, in get_loc
    return self._engine.get_loc(casted_key)
           ^^^^^^^^^^^^^^^^^^^^^^^^^^^^^^^^
  File "index.pyx", line 167, in pandas._libs.index.IndexEngine.get_loc
  File "index.pyx", line 196, in pandas._libs.index.IndexEngine.get_loc
  File "pandas\\_libs\\hashtable_class_helper.pxi", line 7081, in pandas._libs.hashtable.PyObjectHashTable.get_item
  File "pandas\\_libs\\hashtable_class_helper.pxi", line 7089, in pandas._libs.hashtable.PyObjectHashTable.get_item
KeyError: 'Nível de escolaridade\n'

The above exception was the direct cause of the following exception:

Traceback (most recent call last):
  File "C:\Users\brsamd00\Documents\Pessoal\Transportes\dados_reais_final.py", line 25, in <module>
    esc = perfil['Nível de escolaridade\n'].value_counts()
          ~~~~~~^^^^^^^^^^^^^^^^^^^^^^^^^^^
  File "C:\Users\brsamd00\AppData\Roaming\Python\Python312\site-packages\pandas\core\frame.py", line 4102, in __getitem__
    indexer = self.columns.get_loc(key)
              ^^^^^^^^^^^^^^^^^^^^^^^^^
  File "C:\Users\brsamd00\AppData\Roaming\Python\Python312\site-packages\pandas\core\indexes\base.py", line 3812, in get_loc
    raise KeyError(key) from err
KeyError: 'Nível de escolaridade\n'
